Workbook
Name callerimage: INDEX(Assets!$F$2:$F$6, MATCH(Pivot!$H$82, Assets!$E$2:$E$6, 0))
Name RepImage: INDEX(Assets!$C$2:$C$6, MATCH(Pivot!$B$80, Assets!$E$2:$E$6, 0))
Name Slicer_Representative: #N/A

Sheet Data
B1: Call Centre Data
B3: Call number | C3: Customer ID | D3: Duration | E3: Representative | F3: Date of Call | G3: Purchase Amount | H3: Satisfaction Rating | I3: FY | J3: Day of week | K3: Duration Bucket | L3: Rating rounded | Q3: Customer ID | R3: Gedner | S3: Age | T3: City
B4: Call_7271 | C4: C0003 | D4: 116 | E4: R05 | F4: 44927 | G4: 128 | H4: 4.9 | I4: =IF(MONTH(calls[[#This Row],[Date of Call]])<=6, YEAR(calls[[#This Row],[Date of Call]]), YEAR(calls[[#This Row],[Date of Call]])+1) -> 2023 | J4: =TEXT(calls[[#This Row],[Date of Call]],"DDDD") -> Sunday | K4: {=_xlfn.IFS(calls[[#This Row],[Duration]]<=10,"Under 10 mins", calls[[#This Row],[Duration]]<=30, "10 to 30 mins", calls[[#This Row],[Duration]]<=60, "30 to 60 mins", calls[[#This Row],[Duration]]<=120, "1 to 2 hours", TRUE, "More than 2 hours")} -> 1 to 2 hours | L4: =ROUND(calls[[#This Row],[Satisfaction Rating]],0) -> 5 | Q4: C0001 | R4: Male | S4: 41 | T4: Columbus
B5: Call_7272 | C5: C0004 | D5: 119 | E5: R05 | F5: 44927 | G5: 135 | H5: 2.9 | I5: =IF(MONTH(calls[[#This Row],[Date of Call]])<=6, YEAR(calls[[#This Row],[Date of Call]]), YEAR(calls[[#This Row],[Date of Call]])+1) -> 2023 | J5: =TEXT(calls[[#This Row],[Date of Call]],"DDDD") -> Sunday | K5: {=_xlfn.IFS(calls[[#This Row],[Duration]]<=10,"Under 10 mins", calls[[#This Row],[Duration]]<=30, "10 to 30 mins", calls[[#This Row],[Duration]]<=60, "30 to 60 mins", calls[[#This Row],[Duration]]<=120, "1 to 2 hours", TRUE, "More than 2 hours")} -> 1 to 2 hours | L5: =ROUND(calls[[#This Row],[Satisfaction Rating]],0) -> 3 | Q5: C0002 | R5: Male | S5: 31 | T5: Cleveland
B6: Call_7273 | C6: C0005 | D6: 68 | E6: R02 | F6: 44927 | G6: 66 | H6: 4.7 | I6: =IF(MONTH(calls[[#This Row],[Date of Call]])<=6, YEAR(calls[[#This Row],[Date of Call]]), YEAR(calls[[#This Row],[Date of Call]])+1) -> 2023 | J6: =TEXT(calls[[#This Row],[Date of Call]],"DDDD") -> Sunday | K6: {=_xlfn.IFS(calls[[#This Row],[Duration]]<=10,"Under 10 mins", calls[[#This Row],[Duration]]<=30, "10 to 30 mins", calls[[#This Row],[Duration]]<=60, "30 to 60 mins", calls[[#This Row],[Duration]]<=120, "1 to 2 hours", TRUE, "More than 2 hours")} -> 1 to 2 hours | L6: =ROUND(calls[[#This Row],[Satisfaction Rating]],0) -> 5 | Q6: C0003 | R6: Male | S6: 26 | T6: Cincinnati
B7: Call_7274 | C7: C0014 | D7: 119 | E7: R02 | F7: 44927 | G7: 22 | H7: 2.9 | I7: =IF(MONTH(calls[[#This Row],[Date of Call]])<=6, YEAR(calls[[#This Row],[Date of Call]]), YEAR(calls[[#This Row],[Date of Call]])+1) -> 2023 | J7: =TEXT(calls[[#This Row],[Date of Call]],"DDDD") -> Sunday | K7: {=_xlfn.IFS(calls[[#This Row],[Duration]]<=10,"Under 10 mins", calls[[#This Row],[Duration]]<=30, "10 to 30 mins", calls[[#This Row],[Duration]]<=60, "30 to 60 mins", calls[[#This Row],[Duration]]<=120, "1 to 2 hours", TRUE, "More than 2 hours")} -> 1 to 2 hours | L7: =ROUND(calls[[#This Row],[Satisfaction Rating]],0) -> 3 | Q7: C0004 | R7: Male | S7: 36 | T7: Cincinnati
B8: Call_7275 | C8: C0011 | D8: 128 | E8: R01 | F8: 44928 | G8: 31 | H8: 2.8 | I8: =IF(MONTH(calls[[#This Row],[Date of Call]])<=6, YEAR(calls[[#This Row],[Date of Call]]), YEAR(calls[[#This Row],[Date of Call]])+1) -> 2023 | J8: =TEXT(calls[[#This Row],[Date of Call]],"DDDD") -> Monday | K8: {=_xlfn.IFS(calls[[#This Row],[Duration]]<=10,"Under 10 mins", calls[[#This Row],[Duration]]<=30, "10 to 30 mins", calls[[#This Row],[Duration]]<=60, "30 to 60 mins", calls[[#This Row],[Duration]]<=120, "1 to 2 hours", TRUE, "More than 2 hours")} -> More than 2 hours | L8: =ROUND(calls[[#This Row],[Satisfaction Rating]],0) -> 3 | Q8: C0005 | R8: Male | S8: 37 | T8: Columbus
B9: Call_7276 | C9: C0011 | D9: 49 | E9: R02 | F9: 44929 | G9: 135 | H9: 4.8 | I9: =IF(MONTH(calls[[#This Row],[Date of Call]])<=6, YEAR(calls[[#This Row],[Date of Call]]), YEAR(calls[[#This Row],[Date of Call]])+1) -> 2023 | J9: =TEXT(calls[[#This Row],[Date of Call]],"DDDD") -> Tuesday | K9: {=_xlfn.IFS(calls[[#This Row],[Duration]]<=10,"Under 10 mins", calls[[#This Row],[Duration]]<=30, "10 to 30 mins", calls[[#This Row],[Duration]]<=60, "30 to 60 mins", calls[[#This Row],[Duration]]<=120, "1 to 2 hours", TRUE, "More than 2 hours")} -> 30 to 60 mins | L9: =ROUND(calls[[#This Row],[Satisfaction Rating]],0) -> 5 | Q9: C0006 | R9: Male | S9: 23 | T9: Columbus
B10: Call_7277 | C10: C0007 | D10: 84 | E10: R05 | F10: 44929 | G10: 60 | H10: 4.7 | I10: =IF(MONTH(calls[[#This Row],[Date of Call]])<=6, YEAR(calls[[#This Row],[Date of Call]]), YEAR(calls[[#This Row],[Date of Call]])+1) -> 2023 | J10: =TEXT(calls[[#This Row],[Date of Call]],"DDDD") -> Tuesday | K10: {=_xlfn.IFS(calls[[#This Row],[Duration]]<=10,"Under 10 mins", calls[[#This Row],[Duration]]<=30, "10 to 30 mins", calls[[#This Row],[Duration]]<=60, "30 to 60 mins", calls[[#This Row],[Duration]]<=120, "1 to 2 hours", TRUE, "More than 2 hours")} -> 1 to 2 hours | L10: =ROUND(calls[[#This Row],[Satisfaction Rating]],0) -> 5 | Q10: C0007 | R10: Female | S10: 22 | T10: Cleveland
B11: Call_7278 | C11: C0003 | D11: 103 | E11: R04 | F11: 44929 | G11: 148 | H11: 4.4 | I11: =IF(MONTH(calls[[#This Row],[Date of Call]])<=6, YEAR(calls[[#This Row],[Date of Call]]), YEAR(calls[[#This Row],[Date of Call]])+1) -> 2023 | J11: =TEXT(calls[[#This Row],[Date of Call]],"DDDD") -> Tuesday | K11: {=_xlfn.IFS(calls[[#This Row],[Duration]]<=10,"Under 10 mins", calls[[#This Row],[Duration]]<=30, "10 to 30 mins", calls[[#This Row],[Duration]]<=60, "30 to 60 mins", calls[[#This Row],[Duration]]<=120, "1 to 2 hours", TRUE, "More than 2 hours")} -> 1 to 2 hours | L11: =ROUND(calls[[#This Row],[Satisfaction Rating]],0) -> 4 | Q11: C0008 | R11: Female | S11: 42 | T11: Cleveland
B12: Call_7279 | C12: C0005 | D12: 31 | E12: R02 | F12: 44929 | G12: 135 | H12: 3.6 | I12: =IF(MONTH(calls[[#This Row],[Date of Call]])<=6, YEAR(calls[[#This Row],[Date of Call]]), YEAR(calls[[#This Row],[Date of Call]])+1) -> 2023 | J12: =TEXT(calls[[#This Row],[Date of Call]],"DDDD") -> Tuesday | K12: {=_xlfn.IFS(calls[[#This Row],[Duration]]<=10,"Under 10 mins", calls[[#This Row],[Duration]]<=30, "10 to 30 mins", calls[[#This Row],[Duration]]<=60, "30 to 60 mins", calls[[#This Row],[Duration]]<=120, "1 to 2 hours", TRUE, "More than 2 hours")} -> 30 to 60 mins | L12: =ROUND(calls[[#This Row],[Satisfaction Rating]],0) -> 4 | Q12: C0009 | R12: Female | S12: 25 | T12: Columbus
B13: Call_7280 | C13: C0010 | D13: 44 | E13: R03 | F13: 44929 | G13: 105 | H13: 2.9 | I13: =IF(MONTH(calls[[#This Row],[Date of Call]])<=6, YEAR(calls[[#This Row],[Date of Call]]), YEAR(calls[[#This Row],[Date of Call]])+1) -> 2023 | J13: =TEXT(calls[[#This Row],[Date of Call]],"DDDD") -> Tuesday | K13: {=_xlfn.IFS(calls[[#This Row],[Duration]]<=10,"Under 10 mins", calls[[#This Row],[Duration]]<=30, "10 to 30 mins", calls[[#This Row],[Duration]]<=60, "30 to 60 mins", calls[[#This Row],[Duration]]<=120, "1 to 2 hours", TRUE, "More than 2 hours")} -> 30 to 60 mins | L13: =ROUND(calls[[#This Row],[Satisfaction Rating]],0) -> 3 | Q13: C0010 | R13: Female | S13: 30 | T13: Cleveland
B14: Call_7281 | C14: C0011 | D14: 102 | E14: R02 | F14: 44929 | G14: 69 | H14: 4.9 | I14: =IF(MONTH(calls[[#This Row],[Date of Call]])<=6, YEAR(calls[[#This Row],[Date of Call]]), YEAR(calls[[#This Row],[Date of Call]])+1) -> 2023 | J14: =TEXT(calls[[#This Row],[Date of Call]],"DDDD") -> Tuesday | K14: {=_xlfn.IFS(calls[[#This Row],[Duration]]<=10,"Under 10 mins", calls[[#This Row],[Duration]]<=30, "10 to 30 mins", calls[[#This Row],[Duration]]<=60, "30 to 60 mins", calls[[#This Row],[Duration]]<=120, "1 to 2 hours", TRUE, "More than 2 hours")} -> 1 to 2 hours | L14: =ROUND(calls[[#This Row],[Satisfaction Rating]],0) -> 5 | Q14: C0011 | R14: Female | S14: 30 | T14: Cincinnati
B15: Call_7282 | C15: C0013 | D15: 135 | E15: R05 | F15: 44929 | G15: 46 | H15: 3.4 | I15: =IF(MONTH(calls[[#This Row],[Date of Call]])<=6, YEAR(calls[[#This Row],[Date of Call]]), YEAR(calls[[#This Row],[Date of Call]])+1) -> 2023 | J15: =TEXT(calls[[#This Row],[Date of Call]],"DDDD") -> Tuesday | K15: {=_xlfn.IFS(calls[[#This Row],[Duration]]<=10,"Under 10 mins", calls[[#This Row],[Duration]]<=30, "10 to 30 mins", calls[[#This Row],[Duration]]<=60, "30 to 60 mins", calls[[#This Row],[Duration]]<=120, "1 to 2 hours", TRUE, "More than 2 hours")} -> More than 2 hours | L15: =ROUND(calls[[#This Row],[Satisfaction Rating]],0) -> 3 | Q15: C0012 | R15: Female | S15: 28 | T15: Cincinnati
... B18: Call_7285 | C18: C0013 | D18: 48 | E18: R01 | F18: 44930 | G18: 68 | H18: 4.9 | I18: =IF(MONTH(calls[[#This Row],[Date of Call]])<=6, YEAR(calls[[#This Row],[Date of Call]]), YEAR(calls[[#This Row],[Date of Call]])+1) -> 2023 | J18: =TEXT(calls[[#This Row],[Date of Call]],"DDDD") -> Wednesday | K18: {=_xlfn.IFS(calls[[#This Row],[Duration]]<=10,"Under 10 mins", calls[[#This Row],[Duration]]<=30, "10 to 30 mins", calls[[#This Row],[Duration]]<=60, "30 to 60 mins", calls[[#This Row],[Duration]]<=120, "1 to 2 hours", TRUE, "More than 2 hours")} -> 30 to 60 mins | L18: =ROUND(calls[[#This Row],[Satisfaction Rating]],0) -> 5 | Q18: C0015 | R18: Female | S18: 43 | T18: Cleveland
B19: Call_7286 | C19: C0010 | D19: 176 | E19: R05 | F19: 44931 | G19: 24 | H19: 4.8 | I19: =IF(MONTH(calls[[#This Row],[Date of Call]])<=6, YEAR(calls[[#This Row],[Date of Call]]), YEAR(calls[[#This Row],[Date of Call]])+1) -> 2023 | J19: =TEXT(calls[[#This Row],[Date of Call]],"DDDD") -> Thursday | K19: {=_xlfn.IFS(calls[[#This Row],[Duration]]<=10,"Under 10 mins", calls[[#This Row],[Duration]]<=30, "10 to 30 mins", calls[[#This Row],[Duration]]<=60, "30 to 60 mins", calls[[#This Row],[Duration]]<=120, "1 to 2 hours", TRUE, "More than 2 hours")} -> More than 2 hours | L19: =ROUND(calls[[#This Row],[Satisfaction Rating]],0) -> 5
B20: Call_7287 | C20: C0010 | D20: 99 | E20: R01 | F20: 44931 | G20: 195 | H20: 3.9 | I20: =IF(MONTH(calls[[#This Row],[Date of Call]])<=6, YEAR(calls[[#This Row],[Date of Call]]), YEAR(calls[[#This Row],[Date of Call]])+1) -> 2023 | J20: =TEXT(calls[[#This Row],[Date of Call]],"DDDD") -> Thursday | K20: {=_xlfn.IFS(calls[[#This Row],[Duration]]<=10,"Under 10 mins", calls[[#This Row],[Duration]]<=30, "10 to 30 mins", calls[[#This Row],[Duration]]<=60, "30 to 60 mins", calls[[#This Row],[Duration]]<=120, "1 to 2 hours", TRUE, "More than 2 hours")} -> 1 to 2 hours | L20: =ROUND(calls[[#This Row],[Satisfaction Rating]],0) -> 4
B21: Call_7288 | C21: C0009 | D21: 28 | E21: R03 | F21: 44931 | G21: 28 | H21: 3.8 | I21: =IF(MONTH(calls[[#This Row],[Date of Call]])<=6, YEAR(calls[[#This Row],[Date of Call]]), YEAR(calls[[#This Row],[Date of Call]])+1) -> 2023 | J21: =TEXT(calls[[#This Row],[Date of Call]],"DDDD") -> Thursday | K21: {=_xlfn.IFS(calls[[#This Row],[Duration]]<=10,"Under 10 mins", calls[[#This Row],[Duration]]<=30, "10 to 30 mins", calls[[#This Row],[Duration]]<=60, "30 to 60 mins", calls[[#This Row],[Duration]]<=120, "1 to 2 hours", TRUE, "More than 2 hours")} -> 10 to 30 mins | L21: =ROUND(calls[[#This Row],[Satisfaction Rating]],0) -> 4
B22: Call_7289 | C22: C0007 | D22: 54 | E22: R02 | F22: 44931 | G22: 170 | H22: 4.3 | I22: =IF(MONTH(calls[[#This Row],[Date of Call]])<=6, YEAR(calls[[#This Row],[Date of Call]]), YEAR(calls[[#This Row],[Date of Call]])+1) -> 2023 | J22: =TEXT(calls[[#This Row],[Date of Call]],"DDDD") -> Thursday | K22: {=_xlfn.IFS(calls[[#This Row],[Duration]]<=10,"Under 10 mins", calls[[#This Row],[Duration]]<=30, "10 to 30 mins", calls[[#This Row],[Duration]]<=60, "30 to 60 mins", calls[[#This Row],[Duration]]<=120, "1 to 2 hours", TRUE, "More than 2 hours")} -> 30 to 60 mins | L22: =ROUND(calls[[#This Row],[Satisfaction Rating]],0) -> 4
B23: Call_7290 | C23: C0006 | D23: 48 | E23: R05 | F23: 44932 | G23: 30 | H23: 4.4 | I23: =IF(MONTH(calls[[#This Row],[Date of Call]])<=6, YEAR(calls[[#This Row],[Date of Call]]), YEAR(calls[[#This Row],[Date of Call]])+1) -> 2023 | J23: =TEXT(calls[[#This Row],[Date of Call]],"DDDD") -> Friday | K23: {=_xlfn.IFS(calls[[#This Row],[Duration]]<=10,"Under 10 mins", calls[[#This Row],[Duration]]<=30, "10 to 30 mins", calls[[#This Row],[Duration]]<=60, "30 to 60 mins", calls[[#This Row],[Duration]]<=120, "1 to 2 hours", TRUE, "More than 2 hours")} -> 30 to 60 mins | L23: =ROUND(calls[[#This Row],[Satisfaction Rating]],0) -> 4
B24: Call_7291 | C24: C0004 | D24: 128 | E24: R05 | F24: 44932 | G24: 72 | H24: 5 | I24: =IF(MONTH(calls[[#This Row],[Date of Call]])<=6, YEAR(calls[[#This Row],[Date of Call]]), YEAR(calls[[#This Row],[Date of Call]])+1) -> 2023 | J24: =TEXT(calls[[#This Row],[Date of Call]],"DDDD") -> Friday | K24: {=_xlfn.IFS(calls[[#This Row],[Duration]]<=10,"Under 10 mins", calls[[#This Row],[Duration]]<=30, "10 to 30 mins", calls[[#This Row],[Duration]]<=60, "30 to 60 mins", calls[[#This Row],[Duration]]<=120, "1 to 2 hours", TRUE, "More than 2 hours")} -> More than 2 hours | L24: =ROUND(calls[[#This Row],[Satisfaction Rating]],0) -> 5
B25: Call_7292 | C25: C0004 | D25: 38 | E25: R04 | F25: 44933 | G25: 92 | H25: 4.9 | I25: =IF(MONTH(calls[[#This Row],[Date of Call]])<=6, YEAR(calls[[#This Row],[Date of Call]]), YEAR(calls[[#This Row],[Date of Call]])+1) -> 2023 | J25: =TEXT(calls[[#This Row],[Date of Call]],"DDDD") -> Saturday | K25: {=_xlfn.IFS(calls[[#This Row],[Duration]]<=10,"Under 10 mins", calls[[#This Row],[Duration]]<=30, "10 to 30 mins", calls[[#This Row],[Duration]]<=60, "30 to 60 mins", calls[[#This Row],[Duration]]<=120, "1 to 2 hours", TRUE, "More than 2 hours")} -> 30 to 60 mins | L25: =ROUND(calls[[#This Row],[Satisfaction Rating]],0) -> 5
B26: Call_7293 | C26: C0003 | D26: 67 | E26: R04 | F26: 44934 | G26: 165 | H26: 4.5 | I26: =IF(MONTH(calls[[#This Row],[Date of Call]])<=6, YEAR(calls[[#This Row],[Date of Call]]), YEAR(calls[[#This Row],[Date of Call]])+1) -> 2023 | J26: =TEXT(calls[[#This Row],[Date of Call]],"DDDD") -> Sunday | K26: {=_xlfn.IFS(calls[[#This Row],[Duration]]<=10,"Under 10 mins", calls[[#This Row],[Duration]]<=30, "10 to 30 mins", calls[[#This Row],[Duration]]<=60, "30 to 60 mins", calls[[#This Row],[Duration]]<=120, "1 to 2 hours", TRUE, "More than 2 hours")} -> 1 to 2 hours | L26: =ROUND(calls[[#This Row],[Satisfaction Rating]],0) -> 5
B27: Call_7294 | C27: C0015 | D27: 58 | E27: R02 | F27: 44934 | G27: 140 | H27: 2.1 | I27: =IF(MONTH(calls[[#This Row],[Date of Call]])<=6, YEAR(calls[[#This Row],[Date of Call]]), YEAR(calls[[#This Row],[Date of Call]])+1) -> 2023 | J27: =TEXT(calls[[#This Row],[Date of Call]],"DDDD") -> Sunday | K27: {=_xlfn.IFS(calls[[#This Row],[Duration]]<=10,"Under 10 mins", calls[[#This Row],[Duration]]<=30, "10 to 30 mins", calls[[#This Row],[Duration]]<=60, "30 to 60 mins", calls[[#This Row],[Duration]]<=120, "1 to 2 hours", TRUE, "More than 2 hours")} -> 30 to 60 mins | L27: =ROUND(calls[[#This Row],[Satisfaction Rating]],0) -> 2
B28: Call_7295 | C28: C0010 | D28: 54 | E28: R01 | F28: 44934 | G28: 111 | H28: 3.3 | I28: =IF(MONTH(calls[[#This Row],[Date of Call]])<=6, YEAR(calls[[#This Row],[Date of Call]]), YEAR(calls[[#This Row],[Date of Call]])+1) -> 2023 | J28: =TEXT(calls[[#This Row],[Date of Call]],"DDDD") -> Sunday | K28: {=_xlfn.IFS(calls[[#This Row],[Duration]]<=10,"Under 10 mins", calls[[#This Row],[Duration]]<=30, "10 to 30 mins", calls[[#This Row],[Duration]]<=60, "30 to 60 mins", calls[[#This Row],[Duration]]<=120, "1 to 2 hours", TRUE, "More than 2 hours")} -> 30 to 60 mins | L28: =ROUND(calls[[#This Row],[Satisfaction Rating]],0) -> 3
B29: Call_7296 | C29: C0012 | D29: 28 | E29: R05 | F29: 44935 | G29: 63 | H29: 4.1 | I29: =IF(MONTH(calls[[#This Row],[Date of Call]])<=6, YEAR(calls[[#This Row],[Date of Call]]), YEAR(calls[[#This Row],[Date of Call]])+1) -> 2023 | J29: =TEXT(calls[[#This Row],[Date of Call]],"DDDD") -> Monday | K29: {=_xlfn.IFS(calls[[#This Row],[Duration]]<=10,"Under 10 mins", calls[[#This Row],[Duration]]<=30, "10 to 30 mins", calls[[#This Row],[Duration]]<=60, "30 to 60 mins", calls[[#This Row],[Duration]]<=120, "1 to 2 hours", TRUE, "More than 2 hours")} -> 10 to 30 mins | L29: =ROUND(calls[[#This Row],[Satisfaction Rating]],0) -> 4
B30: Call_7297 | C30: C0002 | D30: 73 | E30: R05 | F30: 44935 | G30: 80 | H30: 4.2 | I30: =IF(MONTH(calls[[#This Row],[Date of Call]])<=6, YEAR(calls[[#This Row],[Date of Call]]), YEAR(calls[[#This Row],[Date of Call]])+1) -> 2023 | J30: =TEXT(calls[[#This Row],[Date of Call]],"DDDD") -> Monday | K30: {=_xlfn.IFS(calls[[#This Row],[Duration]]<=10,"Under 10 mins", calls[[#This Row],[Duration]]<=30, "10 to 30 mins", calls[[#This Row],[Duration]]<=60, "30 to 60 mins", calls[[#This Row],[Duration]]<=120, "1 to 2 hours", TRUE, "More than 2 hours")} -> 1 to 2 hours | L30: =ROUND(calls[[#This Row],[Satisfaction Rating]],0) -> 4
... B1003: Call_8270 | C1003: C0009 | D1003: 114 | E1003: R01 | F1003: 45291 | G1003: 40 | H1003: 3.9 | I1003: =IF(MONTH(calls[[#This Row],[Date of Call]])<=6, YEAR(calls[[#This Row],[Date of Call]]), YEAR(calls[[#This Row],[Date of Call]])+1) -> 2024 | J1003: =TEXT(calls[[#This Row],[Date of Call]],"DDDD") -> Sunday | K1003: {=_xlfn.IFS(calls[[#This Row],[Duration]]<=10,"Under 10 mins", calls[[#This Row],[Duration]]<=30, "10 to 30 mins", calls[[#This Row],[Duration]]<=60, "30 to 60 mins", calls[[#This Row],[Duration]]<=120, "1 to 2 hours", TRUE, "More than 2 hours")} -> 1 to 2 hours | L1003: =ROUND(calls[[#This Row],[Satisfaction Rating]],0) -> 4

Sheet Dashboard
F2: Call Centre Report -2023
O20: =IF(OR(Pivot!B80="", Pivot!B80=0), "", Pivot!B80) -> R01 | P20: =IF(OR(Pivot!C80="", Pivot!C80=0), "", Pivot!C80) -> R02 | Q20: =IF(OR(Pivot!D80="", Pivot!D80=0), "", Pivot!D80) -> R03 | R20: =IF(OR(Pivot!E80="", Pivot!E80=0), "", Pivot!E80) -> R04 | S20: =IF(OR(Pivot!F80="", Pivot!F80=0), "", Pivot!F80) -> R05 | T20: =IF(OR(Pivot!G80="", Pivot!G80=0), "", Pivot!G80) -> Grand Total
N21: =IF(OR(Pivot!A81="", Pivot!A81=0), "", Pivot!A81) -> Cincinnati | O21: =IF(OR(Pivot!B81="", Pivot!B81=0), "", Pivot!B81) | P21: =IF(OR(Pivot!C81="", Pivot!C81=0), "", Pivot!C81) | Q21: =IF(OR(Pivot!D81="", Pivot!D81=0), "", Pivot!D81) | R21: =IF(OR(Pivot!E81="", Pivot!E81=0), "", Pivot!E81) | S21: =IF(OR(Pivot!F81="", Pivot!F81=0), "", Pivot!F81) | T21: =IF(OR(Pivot!G81="", Pivot!G81=0), "", Pivot!G81)
N22: =IF(OR(Pivot!A82="", Pivot!A82=0), "", Pivot!A82) -> C0003 | O22: =IF(OR(Pivot!B82="", Pivot!B82=0), "", Pivot!B82) -> 891 | P22: =IF(OR(Pivot!C82="", Pivot!C82=0), "", Pivot!C82) -> 1332 | Q22: =IF(OR(Pivot!D82="", Pivot!D82=0), "", Pivot!D82) -> 1282 | R22: =IF(OR(Pivot!E82="", Pivot!E82=0), "", Pivot!E82) -> 739 | S22: =IF(OR(Pivot!F82="", Pivot!F82=0), "", Pivot!F82) -> 560 | T22: =IF(OR(Pivot!G82="", Pivot!G82=0), "", Pivot!G82) -> 4804
N23: =IF(OR(Pivot!A83="", Pivot!A83=0), "", Pivot!A83) -> C0004 | O23: =IF(OR(Pivot!B83="", Pivot!B83=0), "", Pivot!B83) -> 1991 | P23: =IF(OR(Pivot!C83="", Pivot!C83=0), "", Pivot!C83) -> 1886 | Q23: =IF(OR(Pivot!D83="", Pivot!D83=0), "", Pivot!D83) -> 1206 | R23: =IF(OR(Pivot!E83="", Pivot!E83=0), "", Pivot!E83) -> 884 | S23: =IF(OR(Pivot!F83="", Pivot!F83=0), "", Pivot!F83) -> 1722 | T23: =IF(OR(Pivot!G83="", Pivot!G83=0), "", Pivot!G83) -> 7689
N24: =IF(OR(Pivot!A84="", Pivot!A84=0), "", Pivot!A84) -> C0011 | O24: =IF(OR(Pivot!B84="", Pivot!B84=0), "", Pivot!B84) -> 1163 | P24: =IF(OR(Pivot!C84="", Pivot!C84=0), "", Pivot!C84) -> 1180 | Q24: =IF(OR(Pivot!D84="", Pivot!D84=0), "", Pivot!D84) -> 1616 | R24: =IF(OR(Pivot!E84="", Pivot!E84=0), "", Pivot!E84) -> 1043 | S24: =IF(OR(Pivot!F84="", Pivot!F84=0), "", Pivot!F84) -> 1747 | T24: =IF(OR(Pivot!G84="", Pivot!G84=0), "", Pivot!G84) -> 6749
N25: =IF(OR(Pivot!A85="", Pivot!A85=0), "", Pivot!A85) -> C0012 | O25: =IF(OR(Pivot!B85="", Pivot!B85=0), "", Pivot!B85) -> 1438 | P25: =IF(OR(Pivot!C85="", Pivot!C85=0), "", Pivot!C85) -> 1616 | Q25: =IF(OR(Pivot!D85="", Pivot!D85=0), "", Pivot!D85) -> 866 | R25: =IF(OR(Pivot!E85="", Pivot!E85=0), "", Pivot!E85) -> 829 | S25: =IF(OR(Pivot!F85="", Pivot!F85=0), "", Pivot!F85) -> 2070 | T25: =IF(OR(Pivot!G85="", Pivot!G85=0), "", Pivot!G85) -> 6819
N26: =IF(OR(Pivot!A86="", Pivot!A86=0), "", Pivot!A86) -> Cleveland | O26: =IF(OR(Pivot!B86="", Pivot!B86=0), "", Pivot!B86) | P26: =IF(OR(Pivot!C86="", Pivot!C86=0), "", Pivot!C86) | Q26: =IF(OR(Pivot!D86="", Pivot!D86=0), "", Pivot!D86) | R26: =IF(OR(Pivot!E86="", Pivot!E86=0), "", Pivot!E86) | S26: =IF(OR(Pivot!F86="", Pivot!F86=0), "", Pivot!F86) | T26: =IF(OR(Pivot!G86="", Pivot!G86=0), "", Pivot!G86)
N27: =IF(OR(Pivot!A87="", Pivot!A87=0), "", Pivot!A87) -> C0002 | O27: =IF(OR(Pivot!B87="", Pivot!B87=0), "", Pivot!B87) -> 1233 | P27: =IF(OR(Pivot!C87="", Pivot!C87=0), "", Pivot!C87) -> 223 | Q27: =IF(OR(Pivot!D87="", Pivot!D87=0), "", Pivot!D87) -> 1680 | R27: =IF(OR(Pivot!E87="", Pivot!E87=0), "", Pivot!E87) -> 990 | S27: =IF(OR(Pivot!F87="", Pivot!F87=0), "", Pivot!F87) -> 1508 | T27: =IF(OR(Pivot!G87="", Pivot!G87=0), "", Pivot!G87) -> 5634
N28: =IF(OR(Pivot!A88="", Pivot!A88=0), "", Pivot!A88) -> C0007 | O28: =IF(OR(Pivot!B88="", Pivot!B88=0), "", Pivot!B88) -> 1598 | P28: =IF(OR(Pivot!C88="", Pivot!C88=0), "", Pivot!C88) -> 1907 | Q28: =IF(OR(Pivot!D88="", Pivot!D88=0), "", Pivot!D88) -> 869 | R28: =IF(OR(Pivot!E88="", Pivot!E88=0), "", Pivot!E88) -> 1426 | S28: =IF(OR(Pivot!F88="", Pivot!F88=0), "", Pivot!F88) -> 1416 | T28: =IF(OR(Pivot!G88="", Pivot!G88=0), "", Pivot!G88) -> 7216
N29: =IF(OR(Pivot!A89="", Pivot!A89=0), "", Pivot!A89) -> C0008 | O29: =IF(OR(Pivot!B89="", Pivot!B89=0), "", Pivot!B89) -> 900 | P29: =IF(OR(Pivot!C89="", Pivot!C89=0), "", Pivot!C89) -> 1016 | Q29: =IF(OR(Pivot!D89="", Pivot!D89=0), "", Pivot!D89) -> 960 | R29: =IF(OR(Pivot!E89="", Pivot!E89=0), "", Pivot!E89) -> 940 | S29: =IF(OR(Pivot!F89="", Pivot!F89=0), "", Pivot!F89) -> 1193 | T29: =IF(OR(Pivot!G89="", Pivot!G89=0), "", Pivot!G89) -> 5009
N30: =IF(OR(Pivot!A90="", Pivot!A90=0), "", Pivot!A90) -> C0010 | O30: =IF(OR(Pivot!B90="", Pivot!B90=0), "", Pivot!B90) -> 900 | P30: =IF(OR(Pivot!C90="", Pivot!C90=0), "", Pivot!C90) -> 1470 | Q30: =IF(OR(Pivot!D90="", Pivot!D90=0), "", Pivot!D90) -> 1617 | R30: =IF(OR(Pivot!E90="", Pivot!E90=0), "", Pivot!E90) -> 1314 | S30: =IF(OR(Pivot!F90="", Pivot!F90=0), "", Pivot!F90) -> 941 | T30: =IF(OR(Pivot!G90="", Pivot!G90=0), "", Pivot!G90) -> 6242
N31: =IF(OR(Pivot!A91="", Pivot!A91=0), "", Pivot!A91) -> C0013 | O31: =IF(OR(Pivot!B91="", Pivot!B91=0), "", Pivot!B91) -> 1255 | P31: =IF(OR(Pivot!C91="", Pivot!C91=0), "", Pivot!C91) -> 516 | Q31: =IF(OR(Pivot!D91="", Pivot!D91=0), "", Pivot!D91) -> 1874 | R31: =IF(OR(Pivot!E91="", Pivot!E91=0), "", Pivot!E91) -> 1863 | S31: =IF(OR(Pivot!F91="", Pivot!F91=0), "", Pivot!F91) -> 1722 | T31: =IF(OR(Pivot!G91="", Pivot!G91=0), "", Pivot!G91) -> 7230
N32: =IF(OR(Pivot!A92="", Pivot!A92=0), "", Pivot!A92) -> C0015 | O32: =IF(OR(Pivot!B92="", Pivot!B92=0), "", Pivot!B92) -> 1138 | P32: =IF(OR(Pivot!C92="", Pivot!C92=0), "", Pivot!C92) -> 1898 | Q32: =IF(OR(Pivot!D92="", Pivot!D92=0), "", Pivot!D92) -> 1482 | R32: =IF(OR(Pivot!E92="", Pivot!E92=0), "", Pivot!E92) -> 846 | S32: =IF(OR(Pivot!F92="", Pivot!F92=0), "", Pivot!F92) -> 1154 | T32: =IF(OR(Pivot!G92="", Pivot!G92=0), "", Pivot!G92) -> 6518
... N37: =IF(OR(Pivot!A97="", Pivot!A97=0), "", Pivot!A97) -> C0009 | O37: =IF(OR(Pivot!B97="", Pivot!B97=0), "", Pivot!B97) -> 1415 | P37: =IF(OR(Pivot!C97="", Pivot!C97=0), "", Pivot!C97) -> 1271 | Q37: =IF(OR(Pivot!D97="", Pivot!D97=0), "", Pivot!D97) -> 1214 | R37: =IF(OR(Pivot!E97="", Pivot!E97=0), "", Pivot!E97) -> 1135 | S37: =IF(OR(Pivot!F97="", Pivot!F97=0), "", Pivot!F97) -> 1566 | T37: =IF(OR(Pivot!G97="", Pivot!G97=0), "", Pivot!G97) -> 6601
K38: =Pivot!$I$77 -> %ofcall:22% | N38: =IF(OR(Pivot!A98="", Pivot!A98=0), "", Pivot!A98) -> C0014 | O38: =IF(OR(Pivot!B98="", Pivot!B98=0), "", Pivot!B98) -> 1362 | P38: =IF(OR(Pivot!C98="", Pivot!C98=0), "", Pivot!C98) -> 1363 | Q38: =IF(OR(Pivot!D98="", Pivot!D98=0), "", Pivot!D98) -> 1152 | R38: =IF(OR(Pivot!E98="", Pivot!E98=0), "", Pivot!E98) -> 777 | S38: =IF(OR(Pivot!F98="", Pivot!F98=0), "", Pivot!F98) -> 750 | T38: =IF(OR(Pivot!G98="", Pivot!G98=0), "", Pivot!G98) -> 5404
K39: =Pivot!I78 -> CallRank:1 | U39: =IF(OR(Pivot!H98="", Pivot!H98=0), "", Pivot!H98)
K40: =Pivot!I79 -> AmountRank:2

Sheet Pivot
A3: Call count | B3: Total Amount | C3: Total Duration | D3: Avg. Rating | E3: 5*calls
A4: 1000 | B4: 96623 | C4: 89850 | D4: 3.8854 | E4: 307
A13: Call count | B13: Total Amount | C13: Total Duration | D13: Avg. Rating | E13: 5*calls
A14: 218 | B14: 20581 | C14: 19300 | D14: 3.8706422 | E14: 74
A23: Row Labels | B23: Call count | C23: Call count2
A24: Jan | B24: 19 | C24: 19
A25: Feb | B25: 10 | C25: 10
A26: Mar | B26: 40 | C26: 40
A27: Apr | B27: 40 | C27: 40
A28: May | B28: 13 | C28: 13
A29: Jun | B29: 12 | C29: 12
A30: Jul | B30: 9 | C30: 9
A31: Aug | B31: 13 | C31: 13
A32: Sep | B32: 18 | C32: 18
A33: Oct | B33: 21 | C33: 21
A34: Nov | B34: 14 | C34: 14
A35: Dec | B35: 9 | C35: 9
A36: Grand Total | B36: 218 | C36: 218
A39: Row Labels | B39: Call count
A40: Monday | B40: 24
A41: Tuesday | B41: 44
A42: Wednesday | B42: 36
A43: Thursday | B43: 33
A44: Friday | B44: 29
A45: Saturday | B45: 24
A46: Sunday | B46: 28
A47: Grand Total | B47: 218 | F47: For graph
I49: sel rep | J49: =F60 -> R02
A50: Row Labels | B50: Call count | C50: Total Amount | F50: rep | G50: call | H50: amount | I50: sel call | J50: sel amount
A51: R01 | B51: 189 | C51: 18415 | F51: =A51 -> R01 | G51: =B51 -> 189 | H51: =C51 -> 18415 | I51: =IF(F51=$J$49,G51,NA()) -> #N/A | J51: =IF(F51=$J$49,H51,NA()) -> #N/A
A52: R02 | B52: 218 | C52: 20581 | F52: =A52 -> R02 | G52: =B52 -> 218 | H52: =C52 -> 20581 | I52: =IF(F52=$J$49,G52,NA()) -> 218 | J52: =IF(F52=$J$49,H52,NA()) -> 20581
A53: R03 | B53: 207 | C53: 20872 | F53: =A53 -> R03 | G53: =B53 -> 207 | H53: =C53 -> 20872 | I53: =IF(F53=$J$49,G53,NA()) -> #N/A | J53: =IF(F53=$J$49,H53,NA()) -> #N/A
A54: R04 | B54: 186 | C54: 16651 | F54: =A54 -> R04 | G54: =B54 -> 186 | H54: =C54 -> 16651 | I54: =IF(F54=$J$49,G54,NA()) -> #N/A | J54: =IF(F54=$J$49,H54,NA()) -> #N/A
A55: R05 | B55: 200 | C55: 20104 | F55: =A55 -> R05 | G55: =B55 -> 200 | H55: =C55 -> 20104 | I55: =IF(F55=$J$49,G55,NA()) -> #N/A | J55: =IF(F55=$J$49,H55,NA()) -> #N/A
A56: Grand Total | B56: 1000 | C56: 96623
F59: Row Labels
F60: R02
A62: Call count | B62: Column Labels
A63: Row Labels | B63: Female | C63: Male | D63: Grand Total
A64: Cincinnati | B64: 144 | C64: 132 | D64: 276
...

Sheet Assets
E1: Rep ID | F1: Rep Image
E2: R01
E3: R02
E4: R03
E5: R04
E6: R05

Sheet Sheet2
A1: Data returned for 5*calls, R01 (First 1000 rows).
A3: [$calls].[Call number] | B3: [$calls].[Duration] | C3: [$calls].[Representative] | D3: [$calls].[Date of Call] | E3: [$calls].[Purchase Amount] | F3: [$calls].[Satisfaction Rating] | G3: [$calls].[FY] | H3: [$calls].[Day of week] | I3: [$calls].[Duration Bucket] | J3: [$calls].[Rating rounded] | K3: [$calls].[Month of CALL]
A4: Call_7275 | B4: 128 | C4: R01 | D4: 02-01-2023 | E4: 31 | F4: 2.8 | G4: 2023 | H4: Monday | I4: More than 2 hours | J4: 3 | K4: Jan
A5: Call_7285 | B5: 48 | C5: R01 | D5: 04-01-2023 | E5: 68 | F5: 4.9 | G5: 2023 | H5: Wednesday | I5: 30 to 60 mins | J5: 5 | K5: Jan
A6: Call_7287 | B6: 99 | C6: R01 | D6: 05-01-2023 | E6: 195 | F6: 3.9 | G6: 2023 | H6: Thursday | I6: 1 to 2 hours | J6: 4 | K6: Jan
A7: Call_7295 | B7: 54 | C7: R01 | D7: 08-01-2023 | E7: 111 | F7: 3.3 | G7: 2023 | H7: Sunday | I7: 30 to 60 mins | J7: 3 | K7: Jan
A8: Call_7300 | B8: 155 | C8: R01 | D8: 10-01-2023 | E8: 110 | F8: 4.8 | G8: 2023 | H8: Tuesday | I8: More than 2 hours | J8: 5 | K8: Jan
A9: Call_7303 | B9: 29 | C9: R01 | D9: 12-01-2023 | E9: 170 | F9: 5 | G9: 2023 | H9: Thursday | I9: 10 to 30 mins | J9: 5 | K9: Jan
A10: Call_7315 | B10: 105 | C10: R01 | D10: 18-01-2023 | E10: 56 | F10: 3.6 | G10: 2023 | H10: Wednesday | I10: 1 to 2 hours | J10: 4 | K10: Jan
A11: Call_7317 | B11: 131 | C11: R01 | D11: 19-01-2023 | E11: 78 | F11: 4.4 | G11: 2023 | H11: Thursday | I11: More than 2 hours | J11: 4 | K11: Jan
A12: Call_7321 | B12: 149 | C12: R01 | D12: 20-01-2023 | E12: 72 | F12: 4.3 | G12: 2023 | H12: Friday | I12: More than 2 hours | J12: 4 | K12: Jan
A13: Call_7324 | B13: 157 | C13: R01 | D13: 21-01-2023 | E13: 69 | F13: 4.5 | G13: 2023 | H13: Saturday | I13: More than 2 hours | J13: 5 | K13: Jan
A14: Call_7326 | B14: 83 | C14: R01 | D14: 22-01-2023 | E14: 28 | F14: 4.5 | G14: 2023 | H14: Sunday | I14: 1 to 2 hours | J14: 5 | K14: Jan
... A192: Call_8270 | B192: 114 | C192: R01 | D192: 31-12-2023 | E192: 40 | F192: 3.9 | G192: 2024 | H192: Sunday | I192: 1 to 2 hours | J192: 4 | K192: Dec
